Workbook

Sheet Remake
A1: Material | B1: Material description | C1: บรรจุ | D1: บรรจุ | E1: ราคา | F1: Remake
A2: 58000010 | B2: (4seal) กล่องกระดาษ5ชั้น 450*330*300 mm | C2: 20 ถุง 500G./ ลัง 10 Kg | D2: 40 ถุง 250G./ ลัง 10 Kg | E2: =22/10 -> 2.2 | F2: จะใส่แค่ 10 kg ทั้ง2 ขนาด
A3: 58000006 | B3: All Cafe ลังกระดาษ (287*240*177 mm.) | C3: 6 ถุง 500G./ ลัง 3 kg | E3: =5/3 -> 1.6666667
A4: 58000005 | B4: ลังกระดาษ 3กก. 287*240*177 mm. (No Logo) | C4: 6 ถุง 500G./ ลัง 3 kg | E4: =5/3 -> 1.6666667

Sheet สรุป
A2: Code | B2: Code Name | C2: ยกยอดมา | D2: Preclean | E2: Roast | F2: Pack | G2: คงเหลือ | I2: J3 : G | J2: J3 : KG
A3: 54002340 | B3: สารกาแฟอาราบิก้า | D3: =#REF! -> #REF! | G3: =C3+D3+E3+F3 -> #REF!
A4: 57000000 | B4: เมล็ดกาแฟ Clean Arabica Size S&M | C4: =2001750/1000 -> 2001.75 | D4: =#REF! -> #REF! | E4: =VLOOKUP(A4,#REF!,3,0) -> #REF! | G4: =C4+D4+E4+F4 -> #REF! | I4: 4615220 | J4: =I4/1000 -> 4615.22 | K4: =J4-G4 -> #REF!
A5: 57000001 | B5: เมล็ดกาแฟ Clean Arabica Size L | C5: =8854116/1000 -> 8854.116 | D5: =#REF! -> #REF! | E5: =VLOOKUP(A5,#REF!,3,0) -> #REF! | G5: =C5+D5+E5+F5 -> #REF! | I5: 2119076 | J5: =I5/1000 -> 2119.076 | K5: =J5-G5 -> #REF!
A6: 57000002 | B6: เมล็ดกาแฟ Clean Arabica Size ต่ำกว่า S&M | C6: =163520/1000 -> 163.52 | D6: =#REF! -> #REF! | E6: 0 | G6: =C6+D6+E6+F6 -> #REF! | I6: 6254120 | J6: =I6/1000 -> 6254.12 | K6: =J6-G6 -> #REF!
G7: =C7+D7+E7+F7 -> 0
A8: 54002341 | B8: สารกาแฟโรบัสต้า | D8: =#REF! -> #REF! | E8: 0 | G8: =C8+D8+E8+F8 -> #REF!
A9: 57000003 | B9: เมล็ดกาแฟ Clean Robusta Size mix | C9: =5283220/1000 -> 5283.22 | D9: =#REF! -> #REF! | E9: =VLOOKUP(A9,#REF!,3,0) -> #REF! | G9: =C9+D9+E9+F9 -> #REF! | I9: 8713060 | J9: =I9/1000 -> 8713.06 | K9: =J9-G9 -> #REF!
A10: 57000004 | B10: เมล็ดกาแฟ Clean Robusta Size ต่ำกว่า S&M | C10: =57530/1000 -> 57.53 | D10: =#REF! -> #REF! | E10: 0 | G10: =C10+D10+E10+F10 -> #REF! | I10: 294630 | J10: =I10/1000 -> 294.63 | K10: =J10-G10 -> #REF!
G11: =C11+D11+E11+F11 -> 0
A12: 57000100 | B12: เมล็ดกาแฟคั่ว A80 + R20 | E12: =VLOOKUP(A12,#REF!,3,0) -> #REF! | F12: =#REF! -> #REF! | G12: =C12+D12+E12+F12 -> #REF! | I12: =SUM(I4:I11) -> 21996106 | J12: =I12/1000 -> 21996.106

Sheet PVcode54#301
A1: MvT | B1: (Multiple Items)
A2: Code | B2: 54
A4: Row Labels | B4: Material description | C4: Sum of Quantity in UnE | D4: Sum of Amt.in Loc.Cur. | F4: ราคา
A5: 54002340 | B5: สารกาแฟอาราบิก้า | C5: -137290.81 | D5: -35039995 | E5: =D5 -> -35039995 | F5: =D5/C5 -> 255.22462
A6: 54002341 | B6: สารกาแฟโรบัสต้า | C6: -38128.16 | D6: -7454234.2 | E6: =D6 -> -7454234.2 | F6: =D6/C6 -> 195.50469
A7: Grand Total | C7: -175418.97 | D7: -42494229
A9: MvT | B9: (Multiple Items)
A10: Code | B10: 57
A12: Row Labels | B12: Material description | C12: Sum of Quantity in UnE | D12: Sum of Amt.in Loc.Cur.
A13: 57000000 | B13: เมล็ดกาแฟ Clean Arabica Size S&M | C13: -10300.78 | D13: -2748454.1 | F13: =D13/C13 -> 266.82
A14: 57000001 | B14: เมล็ดกาแฟ Clean Arabica Size L | C14: -117559.88 | D14: -31367327 | F14: =D14/C14 -> 266.82
A15: 57000002 | B15: เมล็ดกาแฟ Clean Arabica Size ต่ำกว่า S&M | C15: -5283.6 | D15: -1409770.1 | E15: =D13+D14+D15 -> -35525551 | F15: =D15/C15 -> 266.82
A16: 57000003 | B16: เมล็ดกาแฟ Clean Robusta Size mix | C16: -33550.24 | D16: -6872095.7 | E16: =D16 -> -6872095.7 | F16: =D16/C16 -> 204.83
A17: Grand Total | C17: -166694.5 | D17: -42397647
A19: Diff | B19: Arabica | C19: =C5-C13-C14-C15 -> -4146.55 | D19: =D5-D13-D14-D15 -> 485556.57 | E19: =E5-E15 -> 485556.57
B20: Robusta | C20: =C6-C16 -> -4577.92 | D20: =D6-D16 -> -582138.56 | E20: =E6-E16 -> -582138.56
C22: =SUM(C19:C21) -> -8724.47 | D22: =SUM(D19:D21) -> -96581.99

Sheet Order 301-305 (เรียง)
A1: Order | B1: Material | C1: Material description | D1: ห้อง
A2: 301000000204 | B2: Semi | C2: Semi เมล็ดกาแฟ | D2: Preclean
A3: 301000000205 | B3: Semi | C3: Semi เมล็ดกาแฟ | D3: Preclean
A4: 301000000206 | B4: Semi | C4: Semi เมล็ดกาแฟ | D4: Preclean
A5: 301000000207 | B5: Semi | C5: Semi เมล็ดกาแฟ | D5: Preclean
A6: 301000000208 | B6: Semi | C6: Semi เมล็ดกาแฟ | D6: Preclean
A7: 301000000212 | B7: Semi | C7: Semi เมล็ดกาแฟ | D7: Preclean
A8: 301000000213 | B8: Semi | C8: Semi เมล็ดกาแฟ | D8: Preclean
A9: 301000000214 | B9: Semi | C9: Semi เมล็ดกาแฟ | D9: Preclean
A10: 301000000215 | B10: Semi | C10: Semi เมล็ดกาแฟ | D10: Preclean
A11: 301000000216 | B11: Semi | C11: Semi เมล็ดกาแฟ | D11: Preclean
A12: 301000000217 | B12: Semi | C12: Semi เมล็ดกาแฟ | D12: Preclean
... A86: 305000000048 | B86: 59100000 | C86: เมล็ดกาแฟ CPR Calibrate MF. 500 G. | D86: Repack

Sheet Order 301-305
A1: Order Preclance | B1: Material | C1: Material description | E1: Material | F1: Material description | G1: Order Packing | H1: Material | I1: Material description | J1: Order repack | K1: Material | L1: Material description
A2: ='301'!A4 -> 301000000204 | B2: Semi | C2: Semi เมล็ดกาแฟ | D2: ='302'!A49 -> 302000000309 | E2: =H2 -> 59000004 | F2: =I2 -> Super Blend 500 G. | G2: ='303 '!A4 -> 303000000309 | H2: ='303 '!B7 -> 59000004 | I2: ='303 '!C7 -> Super Blend 500 G. | J2: ='305'!A4 -> 305000000043 | K2: ='305'!B5 -> 59100000 | L2: ='305'!C5 -> เมล็ดกาแฟ CPR Calibrate MF. 500 G.
A3: ='301'!A8 -> 301000000205 | B3: Semi | C3: Semi เมล็ดกาแฟ | D3: ='302'!A4 -> 302000000311 | E3: =H3 -> 59000001 | F3: =I3 -> เมล็ดกาแฟ CPR Coffee Bean MF. 500 G. | G3: ='303 '!A10 -> 303000000310 | H3: ='303 '!B14 -> 59000001 | I3: ='303 '!C14 -> เมล็ดกาแฟ CPR Coffee Bean MF. 500 G. | J3: ='305'!A7 -> 305000000044 | K3: ='305'!B8 -> 59100000 | L3: ='305'!C8 -> เมล็ดกาแฟ CPR Calibrate MF. 500 G.
A4: ='301'!A12 -> 301000000206 | B4: Semi | C4: Semi เมล็ดกาแฟ | D4: ='302'!A9 -> 302000000310 | E4: =H4 -> 59000002 | F4: =I4 -> GOLD BLEND ALL CAFE' ขนาด 500 G. | G4: ='303 '!A16 -> 303000000311 | H4: ='303 '!B20 -> 59000002 | I4: ='303 '!C20 -> GOLD BLEND ALL CAFE' ขนาด 500 G. | J4: ='305'!A10 -> 305000000045 | K4: ='305'!B11 -> 59100000 | L4: ='305'!C11 -> เมล็ดกาแฟ CPR Calibrate MF. 500 G.
A5: ='301'!A16 -> 301000000207 | B5: Semi | C5: Semi เมล็ดกาแฟ | D5: ='302'!A13 -> 302000000312 | E5: =H5 -> 59000003 | F5: =I5 -> เมล็ดกาแฟคั่ว Classic 1 bag ขนาด 500 G. | G5: ='303 '!A22 -> 303000000312 | H5: ='303 '!B25 -> 59000003 | I5: ='303 '!C25 -> เมล็ดกาแฟคั่ว Classic 1 bag ขนาด 500 G. | J5: ='305'!A13 -> 305000000046 | K5: ='305'!B14 -> 59100000 | L5: ='305'!C14 -> เมล็ดกาแฟ CPR Calibrate MF. 500 G.
A6: ='301'!A19 -> 301000000208 | B6: Semi | C6: Semi เมล็ดกาแฟ | D6: ='302'!A17 -> 302000000313 | E6: =H6 -> 59000002 | F6: =I6 -> GOLD BLEND ALL CAFE' ขนาด 500 G. | G6: ='303 '!A29 -> 303000000313 | H6: ='303 '!B33 -> 59000002 | I6: ='303 '!C33 -> GOLD BLEND ALL CAFE' ขนาด 500 G. | J6: ='305'!A16 -> 305000000047 | K6: ='305'!B17 -> 59100000 | L6: ='305'!C17 -> เมล็ดกาแฟ CPR Calibrate MF. 500 G.
A7: ='301'!A23 -> 301000000212 | B7: Semi | C7: Semi เมล็ดกาแฟ | D7: ='302'!A21 -> 302000000314 | E7: =H7 -> 59000002 | F7: =I7 -> GOLD BLEND ALL CAFE' ขนาด 500 G. | G7: ='303 '!A35 -> 303000000314 | H7: ='303 '!B39 -> 59000002 | I7: ='303 '!C39 -> GOLD BLEND ALL CAFE' ขนาด 500 G. | J7: ='305'!A19 -> 305000000048 | K7: ='305'!B20 -> 59100000 | L7: ='305'!C20 -> เมล็ดกาแฟ CPR Calibrate MF. 500 G.
A8: ='301'!A27 -> 301000000213 | B8: Semi | C8: Semi เมล็ดกาแฟ | D8: ='302'!A26 -> 302000000315 | E8: =H8 -> 59000002 | F8: =I8 -> GOLD BLEND ALL CAFE' ขนาด 500 G. | G8: ='303 '!A41 -> 303000000315 | H8: ='303 '!B45 -> 59000002 | I8: ='303 '!C45 -> GOLD BLEND ALL CAFE' ขนาด 500 G.
A9: ='301'!A31 -> 301000000214 | B9: Semi | C9: Semi เมล็ดกาแฟ | D9: ='302'!A30 -> 302000000316 | E9: =H9 -> 59000002 | F9: =I9 -> GOLD BLEND ALL CAFE' ขนาด 500 G. | G9: ='303 '!A47 -> 303000000316 | H9: ='303 '!B51 -> 59000002 | I9: ='303 '!C51 -> GOLD BLEND ALL CAFE' ขนาด 500 G.
A10: ='301'!A34 -> 301000000215 | B10: Semi | C10: Semi เมล็ดกาแฟ | D10: ='302'!A35 -> 302000000317 | E10: =H10 -> 59000002 | F10: =I10 -> GOLD BLEND ALL CAFE' ขนาด 500 G. | G10: ='303 '!A53 -> 303000000317 | H10: ='303 '!B57 -> 59000002 | I10: ='303 '!C57 -> GOLD BLEND ALL CAFE' ขนาด 500 G.
A11: ='301'!A38 -> 301000000216 | B11: Semi | C11: Semi เมล็ดกาแฟ | D11: ='302'!A40 -> 302000000318 | E11: =H11 -> 59000002 | F11: =I11 -> GOLD BLEND ALL CAFE' ขนาด 500 G. | G11: ='303 '!A59 -> 303000000318 | H11: ='303 '!B63 -> 59000002 | I11: ='303 '!C63 -> GOLD BLEND ALL CAFE' ขนาด 500 G.
A12: ='301'!A42 -> 301000000217 | B12: Semi | C12: Semi เมล็ดกาแฟ | D12: ='302'!A45 -> 302000000319 | E12: =H12 -> 59000002 | F12: =I12 -> GOLD BLEND ALL CAFE' ขนาด 500 G. | G12: ='303 '!A65 -> 303000000319 | H12: ='303 '!B69 -> 59000002 | I12: ='303 '!C69 -> GOLD BLEND ALL CAFE' ขนาด 500 G.
A13: ='301'!A46 -> 301000000218 | B13: Semi | C13: Semi เมล็ดกาแฟ | D13: ='302'!A55 -> 302000000320 | E13: =H13 -> 59000002 | F13: =I13 -> GOLD BLEND ALL CAFE' ขนาด 500 G. | G13: ='303 '!A71 -> 303000000320 | H13: ='303 '!B75 -> 59000002 | I13: ='303 '!C75 -> GOLD BLEND ALL CAFE' ขนาด 500 G.
A14: ='301'!A50 -> 301000000219 | B14: Semi | C14: Semi เมล็ดกาแฟ | D14: ='302'!A60 -> 302000000321 | E14: =H14 -> 59000002 | F14: =I14 -> GOLD BLEND ALL CAFE' ขนาด 500 G. | G14: ='303 '!A77 -> 303000000321 | H14: ='303 '!B81 -> 59000002 | I14: ='303 '!C81 -> GOLD BLEND ALL CAFE' ขนาด 500 G.
A15: ='301'!A53 -> 301000000220 | B15: Semi | C15: Semi เมล็ดกาแฟ | D15: ='302'!A65 -> 302000000322 | E15: =H15 -> 59000002 | F15: =I15 -> GOLD BLEND ALL CAFE' ขนาด 500 G. | G15: ='303 '!A83 -> 303000000322 | H15: ='303 '!B87 -> 59000002 | I15: ='303 '!C87 -> GOLD BLEND ALL CAFE' ขนาด 500 G.
A16: ='301'!A56 -> 301000000221 | B16: Semi | C16: Semi เมล็ดกาแฟ | D16: ='302'!A70 -> 302000000323 | E16: =H16 -> 59000002 | F16: =I16 -> GOLD BLEND ALL CAFE' ขนาด 500 G. | G16: ='303 '!A89 -> 303000000323 | H16: ='303 '!B93 -> 59000002 | I16: ='303 '!C93 -> GOLD BLEND ALL CAFE' ขนาด 500 G.
A17: ='301'!A59 -> 301000000222 | B17: Semi | C17: Semi เมล็ดกาแฟ | D17: ='302'!A74 -> 302000000324 | E17: =H17 -> 59000002 | F17: =I17 -> GOLD BLEND ALL CAFE' ขนาด 500 G. | G17: ='303 '!A95 -> 303000000324 | H17: ='303 '!B99 -> 59000002 | I17: ='303 '!C99 -> GOLD BLEND ALL CAFE' ขนาด 500 G.
A18: ='301'!A62 -> 301000000223 | B18: Semi | C18: Semi เมล็ดกาแฟ | D18: ='302'!A79 -> 302000000325 | E18: =H18 -> 59000002 | F18: =I18 -> GOLD BLEND ALL CAFE' ขนาด 500 G. | G18: ='303 '!A101 -> 303000000325 | H18: ='303 '!B105 -> 59000002 | I18: ='303 '!C105 -> GOLD BLEND ALL CAFE' ขนาด 500 G.
A19: ='301'!A65 -> 301000000224 | B19: Semi | C19: Semi เมล็ดกาแฟ | D19: ='302'!A84 -> 302000000326 | E19: =H19 -> 59000002 | F19: =I19 -> GOLD BLEND ALL CAFE' ขนาด 500 G. | G19: ='303 '!A107 -> 303000000326 | H19: ='303 '!B111 -> 59000002 | I19: ='303 '!C111 -> GOLD BLEND ALL CAFE' ขนาด 500 G.
A20: ='301'!A68 -> 301000000225 | B20: Semi | C20: Semi เมล็ดกาแฟ | D20: ='302'!A88 -> 302000000327 | E20: =H20 -> 59000014 | F20: =I20 -> เมล็ดกาแฟ True Tower ขนาด 500 G. | G20: ='303 '!A113 -> 303000000327 | H20: ='303 '!B117 -> 59000014 | I20: ='303 '!C117 -> เมล็ดกาแฟ True Tower ขนาด 500 G.
A21: ='301'!A72 -> 301000000226 | B21: Semi | C21: Semi เมล็ดกาแฟ | D21: ='302'!A92 -> 302000000328 | E21: =H21 -> 59000002 | F21: =I21 -> GOLD BLEND ALL CAFE' ขนาด 500 G. | G21: ='303 '!A119 -> 303000000328 | H21: ='303 '!B123 -> 59000002 | I21: ='303 '!C123 -> GOLD BLEND ALL CAFE' ขนาด 500 G.
A22: ='301'!A75 -> 301000000227 | B22: Semi | C22: Semi เมล็ดกาแฟ | D22: ='302'!A96 -> 302000000329 | E22: =H22 -> 59000002 | F22: =I22 -> GOLD BLEND ALL CAFE' ขนาด 500 G. | G22: ='303 '!A125 -> 303000000329 | H22: ='303 '!B135 -> 59000002 | I22: ='303 '!C129 -> GOLD BLEND ALL CAFE' ขนาด 500 G.
A23: ='301'!A79 -> 301000000228 | B23: Semi | C23: Semi เมล็ดกาแฟ | D23: ='302'!A100 -> 302000000330 | E23: =H23 -> 59000002 | F23: =I23 -> GOLD BLEND ALL CAFE' ขนาด 500 G. | G23: ='303 '!A131 -> 303000000330 | H23: ='303 '!B135 -> 59000002 | I23: ='303 '!C135 -> GOLD BLEND ALL CAFE' ขนาด 500 G.
D24: ='302'!A104 -> 302000000331 | E24: =H24 -> 59000002 | F24: =I24 -> GOLD BLEND ALL CAFE' ขนาด 500 G. | G24: ='303 '!A137 -> 303000000331 | H24: ='303 '!B141 -> 59000002 | I24: ='303 '!C141 -> GOLD BLEND ALL CAFE' ขนาด 500 G.
D25: ='302'!A108 -> 302000000332 | E25: =H25 -> 59000002 | F25: =I25 -> GOLD BLEND ALL CAFE' ขนาด 500 G. | G25: ='303 '!A143 -> 303000000332 | H25: ='303 '!B147 -> 59000002 | I25: ='303 '!C147 -> GOLD BLEND ALL CAFE' ขนาด 500 G.
D26: ='302'!A112 -> 302000000333 | E26: =H26 -> 59000002 | F26: =I26 -> GOLD BLEND ALL CAFE' ขนาด 500 G. | G26: ='303 '!A149 -> 303000000333 | H26: ='303 '!B153 -> 59000002 | I26: ='303 '!C153 -> GOLD BLEND ALL CAFE' ขนาด 500 G.
D27: ='302'!A116 -> 302000000334 | E27: =H27 -> 59000002 | F27: =I27 -> GOLD BLEND ALL CAFE' ขนาด 500 G. | G27: ='303 '!A155 -> 303000000334 | H27: ='303 '!B159 -> 59000002 | I27: ='303 '!C159 -> GOLD BLEND ALL CAFE' ขนาด 500 G.
D28: ='302'!A120 -> 302000000335 | E28: =H28 -> 59000002 | F28: =I28 -> GOLD BLEND ALL CAFE' ขนาด 500 G. | G28: ='303 '!A161 -> 303000000335 | H28: ='303 '!B165 -> 59000002 | I28: ='303 '!C165 -> GOLD BLEND ALL CAFE' ขนาด 500 G.

Sheet MB51 328
A1: Material | B1: Material description | C1: Plnt | D1: MvT | E1: Movement Type Text | F1: Mat. Doc. | G1: SLoc | H1: Batch | I1: Order | J1: Time | K1: User Name | L1: Item | M1: Suppl.Inv | N1: Reas. | O1: S | P1: Reserv.no. | Q1: Document Header Text | R1: Text | S1: Cost Ctr | T1: G/L acct | U1: PO | V1: Vendor | W1: Asset | X1: Reference | Y1: Manuf. Dte | Z1: EUn | AA1: Quantity in UnE | AB1: Amt.in Loc.Cur. | AC1: Doc. Date | AD1: Pstng Date | AE1: SLED/BBD | AF1: Entry Date | AG1: Quantity | AH1: Group order | AI1: Code | AJ1: GL Name | AK1: หมายเหตุ | AL1: ราคา | AM1: Code สูตรผลิต | AN1: สูตรผลิต
A2: 58000010 | B2: (4seal) กล่องกระดาษ5ชั้น 450*330*300 mm | C2: 0328 | D2: 301 | E2: TF trfr plnt to plnt | F2: 4915104153 | G2: M003 | H2: 20251225 | J2: 09:08:37 | K2: SUTTISIT02 | L2: 0001 | N2: 0000 | P2: 0000000000 | Z2: PC | AA2: -94 | AB2: 0 | AC2: 46204 | AD2: 46204 | AF2: 46204 | AG2: -94 | AH2: =LEFT(I2,3) | AI2: =LEFT(A2,2) -> 58 | AJ2: =VLOOKUP(T2,'GL Name'!A:B,2,0) -> #N/A | AL2: =AB2/AA2 -> 0 | AM2: =VLOOKUP(I2,'Order 301-305 (เรียง)'!A:B,2,0) -> #N/A | AN2: =VLOOKUP(I2,'Order 301-305 (เรียง)'!A:C,3,0) -> #N/A
A3: 58000010 | B3: (4seal) กล่องกระดาษ5ชั้น 450*330*300 mm | C3: 0328 | D3: 301 | E3: TF trfr plnt to plnt | F3: 4915104153 | G3: P003 | H3: 20251225 | J3: 09:08:37 | K3: SUTTISIT02 | L3: 0002 | N3: 0000 | P3: 0000000000 | Z3: PC | AA3: 94 | AB3: 0 | AC3: 46204 | AD3: 46204 | AF3: 46204 | AG3: 94 | AH3: =LEFT(I3,3) | AI3: =LEFT(A3,2) -> 58 | AJ3: =VLOOKUP(T3,'GL Name'!A:B,2,0) -> #N/A | AL3: =AB3/AA3 -> 0 | AM3: =VLOOKUP(I3,'Order 301-305 (เรียง)'!A:B,2,0) -> #N/A | AN3: =VLOOKUP(I3,'Order 301-305 (เรียง)'!A:C,3,0) -> #N/A
A4: 58000003 | B4: Film roll Gold blend 420mm*900m | C4: 0328 | D4: 301 | E4: TF trfr plnt to plnt | F4: 4915104685 | G4: M003 | H4: 20260622 | J4: 09:20:23 | K4: SUTTISIT02 | L4: 0001 | N4: 0000 | P4: 0000000000 | Z4: PC | AA4: -6000 | AB4: 0 | AC4: 46204 | AD4: 46204 | AF4: 46204 | AG4: -6000 | AH4: =LEFT(I4,3) | AI4: =LEFT(A4,2) -> 58 | AJ4: =VLOOKUP(T4,'GL Name'!A:B,2,0) -> #N/A | AL4: =AB4/AA4 -> 0 | AM4: =VLOOKUP(I4,'Order 301-305 (เรียง)'!A:B,2,0) -> #N/A | AN4: =VLOOKUP(I4,'Order 301-305 (เรียง)'!A:C,3,0) -> #N/A
A5: 58000003 | B5: Film roll Gold blend 420mm*900m | C5: 0328 | D5: 301 | E5: TF trfr plnt to plnt | F5: 4915104685 | G5: P003 | H5: 20260622 | J5: 09:20:23 | K5: SUTTISIT02 | L5: 0002 | N5: 0000 | P5: 0000000000 | Z5: PC | AA5: 6000 | AB5: 0 | AC5: 46204 | AD5: 46204 | AF5: 46204 | AG5: 6000 | AH5: =LEFT(I5,3) | AI5: =LEFT(A5,2) -> 58 | AJ5: =VLOOKUP(T5,'GL Name'!A:B,2,0) -> #N/A | AL5: =AB5/AA5 -> 0 | AM5: =VLOOKUP(I5,'Order 301-305 (เรียง)'!A:B,2,0) -> #N/A | AN5: =VLOOKUP(I5,'Order 301-305 (เรียง)'!A:C,3,0) -> #N/A
A6: 58000005 | B6: ลังกระดาษ 3กก. 287*240*177 mm. (No Logo) | C6: 0328 | D6: 301 | E6: TF trfr plnt to plnt | F6: 4915104685 | G6: M003 | H6: 20260124 | J6: 09:20:23 | K6: SUTTISIT02 | L6: 0005 | N6: 0000 | P6: 0000000000 | Z6: PC | AA6: -75 | AB6: 0 | AC6: 46204 | AD6: 46204 | AF6: 46204 | AG6: -75 | AH6: =LEFT(I6,3) | AI6: =LEFT(A6,2) -> 58 | AJ6: =VLOOKUP(T6,'GL Name'!A:B,2,0) -> #N/A | AL6: =AB6/AA6 -> 0 | AM6: =VLOOKUP(I6,'Order 301-305 (เรียง)'!A:B,2,0) -> #N/A | AN6: =VLOOKUP(I6,'Order 301-305 (เรียง)'!A:C,3,0) -> #N/A
A7: 58000005 | B7: ลังกระดาษ 3กก. 287*240*177 mm. (No Logo) | C7: 0328 | D7: 301 | E7: TF trfr plnt to plnt | F7: 4915104685 | G7: P003 | H7: 20260124 | J7: 09:20:23 | K7: SUTTISIT02 | L7: 0006 | N7: 0000 | P7: 0000000000 | Z7: PC | AA7: 75 | AB7: 0 | AC7: 46204 | AD7: 46204 | AF7: 46204 | AG7: 75 | AH7: =LEFT(I7,3) | AI7: =LEFT(A7,2) -> 58 | AJ7: =VLOOKUP(T7,'GL Name'!A:B,2,0) -> #N/A | AL7: =AB7/AA7 -> 0 | AM7: =VLOOKUP(I7,'Order 301-305 (เรียง)'!A:B,2,0) -> #N/A | AN7: =VLOOKUP(I7,'Order 301-305 (เรียง)'!A:C,3,0) -> #N/A
A8: 58000005 | B8: ลังกระดาษ 3กก. 287*240*177 mm. (No Logo) | C8: 0328 | D8: 301 | E8: TF trfr plnt to plnt | F8: 4915104685 | G8: M003 | H8: 20260611 | J8: 09:20:23 | K8: SUTTISIT02 | L8: 0007 | N8: 0000 | P8: 0000000000 | Z8: PC | AA8: -531 | AB8: 0 | AC8: 46204 | AD8: 46204 | AF8: 46204 | AG8: -531 | AH8: =LEFT(I8,3) | AI8: =LEFT(A8,2) -> 58 | AJ8: =VLOOKUP(T8,'GL Name'!A:B,2,0) -> #N/A | AL8: =AB8/AA8 -> 0 | AM8: =VLOOKUP(I8,'Order 301-305 (เรียง)'!A:B,2,0) -> #N/A | AN8: =VLOOKUP(I8,'Order 301-305 (เรียง)'!A:C,3,0) -> #N/A
A9: 58000005 | B9: ลังกระดาษ 3กก. 287*240*177 mm. (No Logo) | C9: 0328 | D9: 301 | E9: TF trfr plnt to plnt | F9: 4915104685 | G9: P003 | H9: 20260611 | J9: 09:20:23 | K9: SUTTISIT02 | L9: 0008 | N9: 0000 | P9: 0000000000 | Z9: PC | AA9: 531 | AB9: 0 | AC9: 46204 | AD9: 46204 | AF9: 46204 | AG9: 531 | AH9: =LEFT(I9,3) | AI9: =LEFT(A9,2) -> 58 | AJ9: =VLOOKUP(T9,'GL Name'!A:B,2,0) -> #N/A | AL9: =AB9/AA9 -> 0 | AM9: =VLOOKUP(I9,'Order 301-305 (เรียง)'!A:B,2,0) -> #N/A | AN9: =VLOOKUP(I9,'Order 301-305 (เรียง)'!A:C,3,0) -> #N/A
A10: 58000009 | B10: สติ๊กเกอร์ Classic Beans (หน้า) | C10: 0328 | D10: 301 | E10: TF trfr plnt to plnt | F10: 4915104685 | G10: P003 | H10: 250607 | J10: 09:20:23 | K10: SUTTISIT02 | L10: 0010 | N10: 0000 | P10: 0000000000 | Z10: EA | AA10: 99 | AB10: 0 | AC10: 46204 | AD10: 46204 | AF10: 46204 | AG10: 99 | AH10: =LEFT(I10,3) | AI10: =LEFT(A10,2) -> 58 | AJ10: =VLOOKUP(T10,'GL Name'!A:B,2,0) -> #N/A | AL10: =AB10/AA10 -> 0 | AM10: =VLOOKUP(I10,'Order 301-305 (เรียง)'!A:B,2,0) -> #N/A | AN10: =VLOOKUP(I10,'Order 301-305 (เรียง)'!A:C,3,0) -> #N/A
A11: 58000009 | B11: สติ๊กเกอร์ Classic Beans (หน้า) | C11: 0328 | D11: 301 | E11: TF trfr plnt to plnt | F11: 4915104685 | G11: M003 | H11: 250607 | J11: 09:20:23 | K11: SUTTISIT02 | L11: 0009 | N11: 0000 | P11: 0000000000 | Z11: EA | AA11: -99 | AB11: 0 | AC11: 46204 | AD11: 46204 | AF11: 46204 | AG11: -99 | AH11: =LEFT(I11,3) | AI11: =LEFT(A11,2) -> 58 | AJ11: =VLOOKUP(T11,'GL Name'!A:B,2,0) -> #N/A | AL11: =AB11/AA11 -> 0 | AM11: =VLOOKUP(I11,'Order 301-305 (เรียง)'!A:B,2,0) -> #N/A | AN11: =VLOOKUP(I11,'Order 301-305 (เรียง)'!A:C,3,0) -> #N/A
A12: 58000025 | B12: Film roll Nologo 500g.420mm*900m | C12: 0328 | D12: 301 | E12: TF trfr plnt to plnt | F12: 4915104685 | G12: P003 | H12: 20250915 | J12: 09:20:23 | K12: SUTTISIT02 | L12: 0004 | N12: 0000 | P12: 0000000000 | Z12: PC | AA12: 3000 | AB12: 0 | AC12: 46204 | AD12: 46204 | AF12: 46204 | AG12: 3000 | AH12: =LEFT(I12,3) | AI12: =LEFT(A12,2) -> 58 | AJ12: =VLOOKUP(T12,'GL Name'!A:B,2,0) -> #N/A | AL12: =AB12/AA12 -> 0 | AM12: =VLOOKUP(I12,'Order 301-305 (เรียง)'!A:B,2,0) -> #N/A | AN12: =VLOOKUP(I12,'Order 301-305 (เรียง)'!A:C,3,0) -> #N/A
A13: 58000025 | B13: Film roll Nologo 500g.420mm*900m | C13: 0328 | D13: 301 | E13: TF trfr plnt to plnt | F13: 4915104685 | G13: M003 | H13: 20250915 | J13: 09:20:23 | K13: SUTTISIT02 | L13: 0003 | N13: 0000 | P13: 0000000000 | Z13: PC | AA13: -3000 | AB13: 0 | AC13: 46204 | AD13: 46204 | AF13: 46204 | AG13: -3000 | AH13: =LEFT(I13,3) | AI13: =LEFT(A13,2) -> 58 | AJ13: =VLOOKUP(T13,'GL Name'!A:B,2,0) -> #N/A | AL13: =AB13/AA13 -> 0 | AM13: =VLOOKUP(I13,'Order 301-305 (เรียง)'!A:B,2,0) -> #N/A | AN13: =VLOOKUP(I13,'Order 301-305 (เรียง)'!A:C,3,0) -> #N/A
A14: 59000002 | B14: GOLD BLEND ALL CAFE' ขนาด 500 G. | C14: 0328 | D14: 927 | E14: GI ค่าวิจัยและพัฒนา | F14: 4915121463 | G14: M001 | H14: 190601-R/B | J14: 13:58:43 | K14: RAPEESAN01 | L14: 0001 | N14: 0000 | P14: 0150823831 | R14: เพื่อส่งให้ RD'QA 7-11 ตรวจสอบ | S14: 405053 | T14: 67501001 | Z14: BAG | AA14: -6 | AB14: -1016.28 | AC14: 46204 | AD14: 46204 | AF14: 46204 | AG14: -3000 | AH14: =LEFT(I14,3) | AI14: =LEFT(A14,2) -> 59 | AJ14: =VLOOKUP(T14,'GL Name'!A:B,2,0) -> ค่าวิจัยคุณภาพสินค้า | AL14: =AB14/AA14 -> 169.38 | AM14: =VLOOKUP(I14,'Order 301-305 (เรียง)'!A:B,2,0) -> #N/A | AN14: =VLOOKUP(I14,'Order 301-305 (เรียง)'!A:C,3,0) -> #N/A
A15: 59000001 | B15: เมล็ดกาแฟ CPR Coffee Bean MF. 500 G. | C15: 0328 | D15: 601 | E15: GD goods issue:delvy | F15: 4915131741 | G15: P004 | H15: 090426-T/B | J15: 14:52:54 | K15: CHONMPRA | L15: 0001 | N15: 0000 | P15: 0000000000 | T15: 51003100 | X15: 2000124686 | Z15: BAG | AA15: -60 | AB15: -10161.6 | AC15: 46204 | AD15: 46204 | AF15: 46204 | AG15: -30000 | AH15: =LEFT(I15,3) | AI15: =LEFT(A15,2) -> 59 | AJ15: =VLOOKUP(T15,'GL Name'!A:B,2,0) -> ต้นทุนขาย | AL15: =AB15/AA15 -> 169.36 | AM15: =VLOOKUP(I15,'Order 301-305 (เรียง)'!A:B,2,0) -> #N/A | AN15: =VLOOKUP(I15,'Order 301-305 (เรียง)'!A:C,3,0) -> #N/A
A16: 59000001 | B16: เมล็ดกาแฟ CPR Coffee Bean MF. 500 G. | C16: 0328 | D16: 601 | E16: GD goods issue:delvy | F16: 4915141309 | G16: P004 | H16: 090426-T/B | J16: 16:08:20 | K16: CHONMPRA | L16: 0001 | N16: 0000 | P16: 0000000000 | T16: 51003100 | X16: 2000124688 | Z16: BAG | AA16: -60 | AB16: -10161.6 | AC16: 46204 | AD16: 46204 | AF16: 46204 | AG16: -30000 | AH16: =LEFT(I16,3) | AI16: =LEFT(A16,2) -> 59 | AJ16: =VLOOKUP(T16,'GL Name'!A:B,2,0) -> ต้นทุนขาย | AL16: =AB16/AA16 -> 169.36 | AM16: =VLOOKUP(I16,'Order 301-305 (เรียง)'!A:B,2,0) -> #N/A | AN16: =VLOOKUP(I16,'Order 301-305 (เรียง)'!A:C,3,0) -> #N/A
A17: 54002341 | B17: สารกาแฟโรบัสต้า | C17: 0328 | D17: 311 | E17: TF trfr within plant | F17: 4915143133 | G17: M002 | H17: 260616-BBB | J17: 16:54:39 | K17: PRONDTAN | L17: 0001 | N17: 0000 | P17: 0000000000 | Z17: KG | AA17: -6988 | AB17: 0 | AC17: 46204 | AD17: 46204 | AF17: 46204 | AG17: -6988000 | AH17: =LEFT(I17,3) | AI17: =LEFT(A17,2) -> 54 | AJ17: =VLOOKUP(T17,'GL Name'!A:B,2,0) -> #N/A | AL17: =AB17/AA17 -> 0 | AM17: =VLOOKUP(I17,'Order 301-305 (เรียง)'!A:B,2,0) -> #N/A | AN17: =VLOOKUP(I17,'Order 301-305 (เรียง)'!A:C,3,0) -> #N/A
A18: 54002341 | B18: สารกาแฟโรบัสต้า | C18: 0328 | D18: 311 | E18: TF trfr within plant | F18: 4915143133 | G18: P001 | H18: 260616-BBB | J18: 16:54:39 | K18: PRONDTAN | L18: 0002 | N18: 0000 | P18: 0000000000 | Z18: KG | AA18: 6988 | AB18: 0 | AC18: 46204 | AD18: 46204 | AF18: 46204 | AG18: 6988000 | AH18: =LEFT(I18,3) | AI18: =LEFT(A18,2) -> 54 | AJ18: =VLOOKUP(T18,'GL Name'!A:B,2,0) -> #N/A | AL18: =AB18/AA18 -> 0 | AM18: =VLOOKUP(I18,'Order 301-305 (เรียง)'!A:B,2,0) -> #N/A | AN18: =VLOOKUP(I18,'Order 301-305 (เรียง)'!A:C,3,0) -> #N/A
A19: 59000002 | B19: GOLD BLEND ALL CAFE' ขนาด 500 G. | C19: 0328 | D19: 601 | E19: GD goods issue:delvy | F19: 4915148334 | G19: M001 | H19: 190601-R/B | J19: 18:34:46 | K19: RAPEESAN01 | L19: 0001 | N19: 0000 | P19: 0000000000 | T19: 51003100 | X19: 2000124696 | Z19: BOX | AA19: -1920 | AB19: -1951257.6 | AC19: 46204 | AD19: 46204 | AF19: 46204 | AG19: -5760000 | AH19: =LEFT(I19,3) | AI19: =LEFT(A19,2) -> 59 | AJ19: =VLOOKUP(T19,'GL Name'!A:B,2,0) -> ต้นทุนขาย | AL19: =AB19/AA19 -> 1016.28 | AM19: =VLOOKUP(I19,'Order 301-305 (เรียง)'!A:B,2,0) -> #N/A | AN19: =VLOOKUP(I19,'Order 301-305 (เรียง)'!A:C,3,0) -> #N/A
A20: 59000002 | B20: GOLD BLEND ALL CAFE' ขนาด 500 G. | C20: 0328 | D20: 601 | E20: GD goods issue:delvy | F20: 4915148461 | G20: M001 | H20: 190602RF/B | J20: 18:36:44 | K20: RAPEESAN01 | L20: 0002 | N20: 0000 | P20: 0000000000 | T20: 51003100 | X20: 2000124697 | Z20: BOX | AA20: -149 | AB20: -151425.72 | AC20: 46204 | AD20: 46204 | AF20: 46204 | AG20: -447000 | AH20: =LEFT(I20,3) | AI20: =LEFT(A20,2) -> 59 | AJ20: =VLOOKUP(T20,'GL Name'!A:B,2,0) -> ต้นทุนขาย | AL20: =AB20/AA20 -> 1016.28 | AM20: =VLOOKUP(I20,'Order 301-305 (เรียง)'!A:B,2,0) -> #N/A | AN20: =VLOOKUP(I20,'Order 301-305 (เรียง)'!A:C,3,0) -> #N/A
A21: 59000002 | B21: GOLD BLEND ALL CAFE' ขนาด 500 G. | C21: 0328 | D21: 601 | E21: GD goods issue:delvy | F21: 4915148461 | G21: M001 | H21: 190601-R/B | J21: 18:36:44 | K21: RAPEESAN01 | L21: 0001 | N21: 0000 | P21: 0000000000 | T21: 51003100 | X21: 2000124697 | Z21: BOX | AA21: -811 | AB21: -824203.08 | AC21: 46204 | AD21: 46204 | AF21: 46204 | AG21: -2433000 | AH21: =LEFT(I21,3) | AI21: =LEFT(A21,2) -> 59 | AJ21: =VLOOKUP(T21,'GL Name'!A:B,2,0) -> ต้นทุนขาย | AL21: =AB21/AA21 -> 1016.28 | AM21: =VLOOKUP(I21,'Order 301-305 (เรียง)'!A:B,2,0) -> #N/A | AN21: =VLOOKUP(I21,'Order 301-305 (เรียง)'!A:C,3,0) -> #N/A
A22: 59000002 | B22: GOLD BLEND ALL CAFE' ขนาด 500 G. | C22: 0328 | D22: 927 | E22: GI ค่าวิจัยและพัฒนา | F22: 4915148620 | G22: M001 | H22: 190601-R/B | J22: 18:41:37 | K22: RAPEESAN01 | L22: 0001 | N22: 0000 | P22: 0150838045 | R22: Routine 01.07.26.1 A010R002 | S22: 405053 | T22: 67501001 | Z22: BAG | AA22: -2 | AB22: -338.76 | AC22: 46204 | AD22: 46204 | AF22: 46204 | AG22: -1000 | AH22: =LEFT(I22,3) | AI22: =LEFT(A22,2) -> 59 | AJ22: =VLOOKUP(T22,'GL Name'!A:B,2,0) -> ค่าวิจัยคุณภาพสินค้า | AL22: =AB22/AA22 -> 169.38 | AM22: =VLOOKUP(I22,'Order 301-305 (เรียง)'!A:B,2,0) -> #N/A | AN22: =VLOOKUP(I22,'Order 301-305 (เรียง)'!A:C,3,0) -> #N/A
A23: 59000002 | B23: GOLD BLEND ALL CAFE' ขนาด 500 G. | C23: 0328 | D23: 927 | E23: GI ค่าวิจัยและพัฒนา | F23: 4915148620 | G23: M001 | H23: 190601-R/B | J23: 18:41:37 | K23: RAPEESAN01 | L23: 0002 | N23: 0000 | P23: 0150838045 | R23: Retain 01.07.26.1 A010R002 | S23: 405053 | T23: 67501001 | Z23: BAG | AA23: -2 | AB23: -338.76 | AC23: 46204 | AD23: 46204 | AF23: 46204 | AG23: -1000 | AH23: =LEFT(I23,3) | AI23: =LEFT(A23,2) -> 59 | AJ23: =VLOOKUP(T23,'GL Name'!A:B,2,0) -> ค่าวิจัยคุณภาพสินค้า | AL23: =AB23/AA23 -> 169.38 | AM23: =VLOOKUP(I23,'Order 301-305 (เรียง)'!A:B,2,0) -> #N/A | AN23: =VLOOKUP(I23,'Order 301-305 (เรียง)'!A:C,3,0) -> #N/A
A24: 59100000 | B24: เมล็ดกาแฟ CPR Calibrate MF. 500 G. | C24: 0328 | D24: 927 | E24: GI ค่าวิจัยและพัฒนา | F24: 4915148882 | G24: M001 | H24: 260505-T/B | J24: 18:47:28 | K24: RAPEESAN01 | L24: 0002 | N24: 0000 | P24: 0150837958 | R24: RD ทดสอบ Grade B | S24: 405053 | T24: 67501001 | Z24: BAG | AA24: -4 | AB24: -677.44 | AC24: 46204 | AD24: 46204 | AF24: 46204 | AG24: -2000 | AH24: =LEFT(I24,3) | AI24: =LEFT(A24,2) -> 59 | AJ24: =VLOOKUP(T24,'GL Name'!A:B,2,0) -> ค่าวิจัยคุณภาพสินค้า | AL24: =AB24/AA24 -> 169.36 | AM24: =VLOOKUP(I24,'Order 301-305 (เรียง)'!A:B,2,0) -> #N/A | AN24: =VLOOKUP(I24,'Order 301-305 (เรียง)'!A:C,3,0) -> #N/A
A25: 59100000 | B25: เมล็ดกาแฟ CPR Calibrate MF. 500 G. | C25: 0328 | D25: 927 | E25: GI ค่าวิจัยและพัฒนา | F25: 4915148882 | G25: M001 | H25: 260505-FG | J25: 18:47:28 | K25: RAPEESAN01 | L25: 0001 | N25: 0000 | P25: 0150837958 | R25: RD ทดสอบ Grade B | S25: 405053 | T25: 67501001 | Z25: BAG | AA25: -5 | AB25: -846.8 | AC25: 46204 | AD25: 46204 | AF25: 46204 | AG25: -2500 | AH25: =LEFT(I25,3) | AI25: =LEFT(A25,2) -> 59 | AJ25: =VLOOKUP(T25,'GL Name'!A:B,2,0) -> ค่าวิจัยคุณภาพสินค้า | AL25: =AB25/AA25 -> 169.36 | AM25: =VLOOKUP(I25,'Order 301-305 (เรียง)'!A:B,2,0) -> #N/A | AN25: =VLOOKUP(I25,'Order 301-305 (เรียง)'!A:C,3,0) -> #N/A
A26: 59000001 | B26: เมล็ดกาแฟ CPR Coffee Bean MF. 500 G. | C26: 0328 | D26: 601 | E26: GD goods issue:delvy | F26: 4915200389 | G26: P004 | H26: 090426-T/B | J26: 07:51:15 | K26: SONGPCHI | L26: 0001 | N26: 0000 | P26: 0000000000 | T26: 51003100 | X26: 2000124709 | Z26: G | AA26: -2 | AB26: -0.68 | AC26: 46205 | AD26: 46205 | AF26: 46205 | AG26: -2 | AH26: =LEFT(I26,3) | AI26: =LEFT(A26,2) -> 59 | AJ26: =VLOOKUP(T26,'GL Name'!A:B,2,0) -> ต้นทุนขาย | AK26: CN | AL26: =AB26/AA26 -> 0.34 | AM26: =VLOOKUP(I26,'Order 301-305 (เรียง)'!A:B,2,0) -> #N/A | AN26: =VLOOKUP(I26,'Order 301-305 (เรียง)'!A:C,3,0) -> #N/A
A27: 59000001 | B27: เมล็ดกาแฟ CPR Coffee Bean MF. 500 G. | C27: 0328 | D27: 601 | E27: GD goods issue:delvy | F27: 4915200524 | G27: P004 | H27: 090426-T/B | J27: 07:52:00 | K27: SONGPCHI | L27: 0001 | N27: 0000 | P27: 0000000000 | T27: 51003100 | X27: 2000124710 | Z27: BAG | AA27: -1 | AB27: -169.36 | AC27: 46205 | AD27: 46205 | AF27: 46205 | AG27: -500 | AH27: =LEFT(I27,3) | AI27: =LEFT(A27,2) -> 59 | AJ27: =VLOOKUP(T27,'GL Name'!A:B,2,0) -> ต้นทุนขาย | AL27: =AB27/AA27 -> 169.36 | AM27: =VLOOKUP(I27,'Order 301-305 (เรียง)'!A:B,2,0) -> #N/A | AN27: =VLOOKUP(I27,'Order 301-305 (เรียง)'!A:C,3,0) -> #N/A
A28: 59000001 | B28: เมล็ดกาแฟ CPR Coffee Bean MF. 500 G. | C28: 0328 | D28: 601 | E28: GD goods issue:delvy | F28: 4915200528 | G28: P004 | H28: 090426-T/B | J28: 07:52:46 | K28: SONGPCHI | L28: 0001 | N28: 0000 | P28: 0000000000 | T28: 51003100 | X28: 2000124711 | Z28: BAG | AA28: -1 | AB28: -169.36 | AC28: 46205 | AD28: 46205 | AF28: 46205 | AG28: -500 | AH28: =LEFT(I28,3) | AI28: =LEFT(A28,2) -> 59 | AJ28: =VLOOKUP(T28,'GL Name'!A:B,2,0) -> ต้นทุนขาย | AL28: =AB28/AA28 -> 169.36 | AM28: =VLOOKUP(I28,'Order 301-305 (เรียง)'!A:B,2,0) -> #N/A | AN28: =VLOOKUP(I28,'Order 301-305 (เรียง)'!A:C,3,0) -> #N/A
A29: 59000001 | B29: เมล็ดกาแฟ CPR Coffee Bean MF. 500 G. | C29: 0328 | D29: 601 | E29: GD goods issue:delvy | F29: 4915200553 | G29: P004 | H29: 090426-T/B | J29: 07:54:00 | K29: SONGPCHI | L29: 0001 | N29: 0000 | P29: 0000000000 | T29: 51003100 | X29: 2000124712 | Z29: BAG | AA29: -2 | AB29: -338.72 | AC29: 46205 | AD29: 46205 | AF29: 46205 | AG29: -1000 | AH29: =LEFT(I29,3) | AI29: =LEFT(A29,2) -> 59 | AJ29: =VLOOKUP(T29,'GL Name'!A:B,2,0) -> ต้นทุนขาย | AL29: =AB29/AA29 -> 169.36 | AM29: =VLOOKUP(I29,'Order 301-305 (เรียง)'!A:B,2,0) -> #N/A | AN29: =VLOOKUP(I29,'Order 301-305 (เรียง)'!A:C,3,0) -> #N/A
A30: 59000001 | B30: เมล็ดกาแฟ CPR Coffee Bean MF. 500 G. | C30: 0328 | D30: 601 | E30: GD goods issue:delvy | F30: 4915203368 | G30: P004 | H30: 090426-T/B | J30: 09:24:07 | K30: CHONMPRA | L30: 0001 | N30: 0000 | P30: 0000000000 | T30: 51003100 | X30: 2000124725 | Z30: BAG | AA30: -20 | AB30: -3387.2 | AC30: 46205 | AD30: 46205 | AF30: 46205 | AG30: -10000 | AH30: =LEFT(I30,3) | AI30: =LEFT(A30,2) -> 59 | AJ30: =VLOOKUP(T30,'GL Name'!A:B,2,0) -> ต้นทุนขาย | AL30: =AB30/AA30 -> 169.36 | AM30: =VLOOKUP(I30,'Order 301-305 (เรียง)'!A:B,2,0) -> #N/A | AN30: =VLOOKUP(I30,'Order 301-305 (เรียง)'!A:C,3,0) -> #N/A
A31: 59000001 | B31: เมล็ดกาแฟ CPR Coffee Bean MF. 500 G. | C31: 0328 | D31: 261 | E31: GI for order | F31: 4915205378 | G31: M001 | H31: 260505-T/B | I31: 305000000043 | J31: 10:16:45 | K31: JURASDOK | L31: 0002 | N31: 0000 | P31: 0000000000 | R31: เมล็ดกาแฟ CPR Coffee Bean MF. 500 G. | T31: 53001000 | Z31: BAG | AA31: -9 | AB31: -1524.24 | AC31: 46205 | AD31: 46204 | AF31: 46205 | AG31: -4500 | AH31: =LEFT(I31,3) -> 305 | AI31: =LEFT(A31,2) -> 59 | AJ31: =VLOOKUP(T31,'GL Name'!A:B,2,0) -> ต้นทุนผลิต-สินค้าสำเร็จรูป | AL31: =AB31/AA31 -> 169.36 | AM31: =VLOOKUP(I31,'Order 301-305 (เรียง)'!A:B,2,0) -> 59100000 | AN31: =VLOOKUP(I31,'Order 301-305 (เรียง)'!A:C,3,0) -> เมล็ดกาแฟ CPR Calibrate MF. 500 G.
A32: 59100000 | B32: เมล็ดกาแฟ CPR Calibrate MF. 500 G. | C32: 0328 | D32: 101 | E32: GR for order | F32: 4915205378 | G32: M001 | H32: 260505-T/B | I32: 305000000043 | J32: 10:16:45 | K32: JURASDOK | L32: 0001 | N32: 0000 | P32: 0000000000 | T32: 53001001 | Z32: BAG | AA32: 9 | AB32: 1524.24 | AC32: 46205 | AD32: 46204 | AF32: 46205 | AG32: 4500 | AH32: =LEFT(I32,3) -> 305 | AI32: =LEFT(A32,2) -> 59 | AJ32: =VLOOKUP(T32,'GL Name'!A:B,2,0) -> ต้นทุนผลิตโอน F/G | AL32: =AB32/AA32 -> 169.36 | AM32: =VLOOKUP(I32,'Order 301-305 (เรียง)'!A:B,2,0) -> 59100000 | AN32: =VLOOKUP(I32,'Order 301-305 (เรียง)'!A:C,3,0) -> เมล็ดกาแฟ CPR Calibrate MF. 500 G.
A33: 59100000 | B33: เมล็ดกาแฟ CPR Calibrate MF. 500 G. | C33: 0328 | D33: 301 | E33: TF trfr plnt to plnt | F33: 4915205380 | G33: M001 | H33: 260505-T/B | J33: 10:17:27 | K33: JURASDOK | L33: 0001 | N33: 0000 | P33: 0150733255 | Z33: BAG | AA33: -900 | AB33: -152424 | AC33: 46205 | AD33: 46205 | AF33: 46205 | AG33: -450000 | AH33: =LEFT(I33,3) | AI33: =LEFT(A33,2) -> 59 | AJ33: =VLOOKUP(T33,'GL Name'!A:B,2,0) -> #N/A | AL33: =AB33/AA33 -> 169.36 | AM33: =VLOOKUP(I33,'Order 301-305 (เรียง)'!A:B,2,0) -> #N/A | AN33: =VLOOKUP(I33,'Order 301-305 (เรียง)'!A:C,3,0) -> #N/A
A34: 59000004 | B34: Super Blend 500 G. | C34: 0328 | D34: 101 | E34: GR for order | F34: 4915205759 | G34: M001 | H34: 260701 | I34: 303000000309 | J34: 10:26:29 | K34: JURASDOK | L34: 0001 | N34: 0000 | P34: 0000000000 | T34: 53001001 | Z34: BAG | AA34: 1520 | AB34: 217466.4 | AC34: 46205 | AD34: 46204 | AF34: 46205 | AG34: 760000 | AH34: =LEFT(I34,3) -> 303 | AI34: =LEFT(A34,2) -> 59 | AJ34: =VLOOKUP(T34,'GL Name'!A:B,2,0) -> ต้นทุนผลิตโอน F/G | AL34: =AB34/AA34 -> 143.07 | AM34: =VLOOKUP(I34,'Order 301-305 (เรียง)'!A:B,2,0) -> 59000004 | AN34: =VLOOKUP(I34,'Order 301-305 (เรียง)'!A:C,3,0) -> Super Blend 500 G.
A35: 59000013 | B35: กาแฟมวลชน Gold Blend ขนาด 500 G. | C35: 0328 | D35: 601 | E35: GD goods issue:delvy | F35: 4915207160 | G35: P004 | H35: 280226-RE | J35: 11:03:17 | K35: THANAWIS | L35: 0001 | N35: 0000 | P35: 0000000000 | T35: 51003100 | X35: 2000124731 | Z35: BAG | AA35: -20 | AB35: -3509.4 | AC35: 46205 | AD35: 46205 | AF35: 46205 | AG35: -10000 | AH35: =LEFT(I35,3) | AI35: =LEFT(A35,2) -> 59 | AJ35: =VLOOKUP(T35,'GL Name'!A:B,2,0) -> ต้นทุนขาย | AL35: =AB35/AA35 -> 175.47 | AM35: =VLOOKUP(I35,'Order 301-305 (เรียง)'!A:B,2,0) -> #N/A | AN35: =VLOOKUP(I35,'Order 301-305 (เรียง)'!A:C,3,0) -> #N/A
A36: 59000013 | B36: กาแฟมวลชน Gold Blend ขนาด 500 G. | C36: 0328 | D36: 601 | E36: GD goods issue:delvy | F36: 4915214155 | G36: P004 | H36: 280226-RE | J36: 12:59:36 | K36: THANAWIS | L36: 0001 | N36: 0000 | P36: 0000000000 | T36: 51003100 | X36: 2000124768 | Z36: BAG | AA36: -2 | AB36: -350.94 | AC36: 46205 | AD36: 46205 | AF36: 46205 | AG36: -1000 | AH36: =LEFT(I36,3) | AI36: =LEFT(A36,2) -> 59 | AJ36: =VLOOKUP(T36,'GL Name'!A:B,2,0) -> ต้นทุนขาย | AL36: =AB36/AA36 -> 175.47 | AM36: =VLOOKUP(I36,'Order 301-305 (เรียง)'!A:B,2,0) -> #N/A | AN36: =VLOOKUP(I36,'Order 301-305 (เรียง)'!A:C,3,0) -> #N/A
A37: 59000001 | B37: เมล็ดกาแฟ CPR Coffee Bean MF. 500 G. | C37: 0328 | D37: 601 | E37: GD goods issue:delvy | F37: 4915223591 | G37: P004 | H37: 090426-T/B | J37: 14:13:16 | K37: SONGPCHI | L37: 0001 | N37: 0000 | P37: 0000000000 | T37: 51003100 | X37: 2000124780 | Z37: BAG | AA37: -2 | AB37: -338.72 | AC37: 46205 | AD37: 46205 | AF37: 46205 | AG37: -1000 | AH37: =LEFT(I37,3) | AI37: =LEFT(A37,2) -> 59 | AJ37: =VLOOKUP(T37,'GL Name'!A:B,2,0) -> ต้นทุนขาย | AL37: =AB37/AA37 -> 169.36 | AM37: =VLOOKUP(I37,'Order 301-305 (เรียง)'!A:B,2,0) -> #N/A | AN37: =VLOOKUP(I37,'Order 301-305 (เรียง)'!A:C,3,0) -> #N/A
A38: 59000001 | B38: เมล็ดกาแฟ CPR Coffee Bean MF. 500 G. | C38: 0328 | D38: 601 | E38: GD goods issue:delvy | F38: 4915223597 | G38: P004 | H38: 090426-T/B | J38: 14:16:31 | K38: SONGPCHI | L38: 0001 | N38: 0000 | P38: 0000000000 | T38: 51003100 | X38: 2000124781 | Z38: BAG | AA38: -2 | AB38: -338.72 | AC38: 46205 | AD38: 46205 | AF38: 46205 | AG38: -1000 | AH38: =LEFT(I38,3) | AI38: =LEFT(A38,2) -> 59 | AJ38: =VLOOKUP(T38,'GL Name'!A:B,2,0) -> ต้นทุนขาย | AL38: =AB38/AA38 -> 169.36 | AM38: =VLOOKUP(I38,'Order 301-305 (เรียง)'!A:B,2,0) -> #N/A | AN38: =VLOOKUP(I38,'Order 301-305 (เรียง)'!A:C,3,0) -> #N/A
A39: 59000001 | B39: เมล็ดกาแฟ CPR Coffee Bean MF. 500 G. | C39: 0328 | D39: 601 | E39: GD goods issue:delvy | F39: 4915224194 | G39: P004 | H39: 090426-T/B | J39: 14:17:50 | K39: SONGPCHI | L39: 0001 | N39: 0000 | P39: 0000000000 | T39: 51003100 | X39: 2000124782 | Z39: BAG | AA39: -2 | AB39: -338.72 | AC39: 46205 | AD39: 46205 | AF39: 46205 | AG39: -1000 | AH39: =LEFT(I39,3) | AI39: =LEFT(A39,2) -> 59 | AJ39: =VLOOKUP(T39,'GL Name'!A:B,2,0) -> ต้นทุนขาย | AL39: =AB39/AA39 -> 169.36 | AM39: =VLOOKUP(I39,'Order 301-305 (เรียง)'!A:B,2,0) -> #N/A | AN39: =VLOOKUP(I39,'Order 301-305 (เรียง)'!A:C,3,0) -> #N/A
A40: 59000001 | B40: เมล็ดกาแฟ CPR Coffee Bean MF. 500 G. | C40: 0328 | D40: 601 | E40: GD goods issue:delvy | F40: 4915224564 | G40: P004 | H40: 090426-T/B | J40: 14:19:31 | K40: SONGPCHI | L40: 0001 | N40: 0000 | P40: 0000000000 | T40: 51003100 | X40: 2000124783 | Z40: BAG | AA40: -8 | AB40: -1354.88 | AC40: 46205 | AD40: 46205 | AF40: 46205 | AG40: -4000 | AH40: =LEFT(I40,3) | AI40: =LEFT(A40,2) -> 59 | AJ40: =VLOOKUP(T40,'GL Name'!A:B,2,0) -> ต้นทุนขาย | AL40: =AB40/AA40 -> 169.36 | AM40: =VLOOKUP(I40,'Order 301-305 (เรียง)'!A:B,2,0) -> #N/A | AN40: =VLOOKUP(I40,'Order 301-305 (เรียง)'!A:C,3,0) -> #N/A
...

Sheet GL Name
A1: 51003100 | B1: ต้นทุนขาย | C1: 328
A2: 53001001 | B2: ต้นทุนผลิตโอน F/G | C2: 328
A3: 53001003 | B3: ต้นทุนผลิตกึ่งสำเร็จ | C3: 328
A4: 53001004 | B4: ต้นทุนผลิตโอน Semi | C4: 328
A5: 53002000 | B5: ต้นทุนผลิต-วัตถุดิบ | C5: 328
A6: 53003000 | B6: ต้นทุนผลิตหีบห่อ | C6: 328
A7: 67501001 | B7: ค่าวิจัยคุณภาพสินค้า | C7: 328
A8: 67601000 | B8: ค่าเชื้อเพลิง | C8: 328
A9: 53001000 | B9: ต้นทุนผลิต-สินค้าสำเร็จรูป | C9: 328
A10: 65109000 | B10: ส่งเสริมฯ อื่น | C10: 328
A11: 53001006 | B11: ต้นทุนผลิต-สินค้าสำเร็จรูป (V2) | C11: 321
A12: 66001000 | B12: วัสดุสิ้นเปลือง | C12: 321
... A14: 51004001 | B14: สินค้าขาด(เกิน)บัญชี | C14: 328

Sheet 301
A1: Group order | B1: 301 | C1: ห้อง Preclean | Q1: Size ต่ำกว่า S&M เกรด B จะเป็นปริมาณ สารกาแฟที่ดี
A3: Row Labels | B3: Material | C3: Material description | D3: EUn | E3: Sum of Quantity in UnE | F3: Sum of Amt.in Loc.Cur. | G3: Semi | H3: สัดส่วน | I3: ราคา/Kg. | J3: % | K3: ปันใหม่ตาม STD | L3: ราคาหลังปัน | M3: Settlement Rule | N3: % Yeild | O3: % Loss | P3: สถานะ | Q3: Por Ver | V3: Q : KG
A4: 301000000204 | B4: 54002340 | C4: สารกาแฟอาราบิก้า | D4: KG | E4: -10030.5 | F4: -2646750.2 | G4: =E5+E6 -> 10025 | H4: =E4/$E$4 -> 1 | I4: =F4/E4 -> 263.87022 | Q4: 101 | S4: 54002340 | T4: สารกาแฟอาราบิก้า | V4: =SUMIF(B:B,S4,E:E) -> -211394.1
B5: 57000001 | C5: เมล็ดกาแฟ Clean Arabica Size L | D5: KG | E5: 9853.2 | F5: 2658294.8 | H5: =E5/$E$4 -> -0.98232391 | I5: =F5/E5 -> 269.79 | J5: 80 | K5: =-F4*J5/J7 -> 2551084.6 | L5: =K5/E5 -> 258.90924 | M5: =ROUND(H5,2) -> -0.98 | S5: 57000000 | T5: เมล็ดกาแฟ Clean Arabica Size S&M | V5: =SUMIF(B:B,S5,E:E) -> 0
B6: 57000002 | C6: เมล็ดกาแฟ Clean Arabica B | D6: KG | E6: 171.8 | F6: 46349.92 | H6: =E6/$E$4 -> -0.01712776 | I6: =F6/E6 -> 269.78999 | J6: 3 | K6: =-F4*J6/J7 -> 95665.671 | L6: =K6/E6 -> 556.84325 | M6: =ROUND(H6,2) -> -0.02 | S6: 57000001 | T6: เมล็ดกาแฟ Clean Arabica Size L | V6: =SUMIF(B:B,S6,E:E) -> 208695.08
A7: 301000000204 Sum | E7: -5.5 | F7: 57894.52 | H7: =E7/$E$4 -> 0.0005483276 | J7: =SUM(J5:J6) -> 83 | K7: =SUM(K5:K6) -> 2646750.2 | M7: =SUM(M5:M6) -> -1 | N7: =SUM(H5:H6) -> -0.99945167 | O7: =-100%-N7 -> -0.0005483276 | P7: Adj Settlement Rule Done | S7: 57000002 | T7: เมล็ดกาแฟ Clean Arabica Size ต่ำกว่า S&M | V7: =SUMIF(B:B,S7,E:E) -> 2111 | W7: =SUM(V4:V7) -> -588.02
A8: 301000000205 | B8: 54002341 | C8: สารกาแฟโรบัสต้า | D8: KG | E8: -10045.8 | F8: -1565128.3 | G8: =+E9+E10 -> 10030.2 | H8: =E8/$E$8 -> 1 | I8: =F8/E8 -> 155.79927 | Q8: 101
B9: 57000003 | C9: เมล็ดกาแฟ Clean Robusta Size mix | D9: KG | E9: 9891 | F9: 1588692.4 | H9: =E9/$E$8 -> -0.98459058 | I9: =F9/E9 -> 160.62 | J9: 95 | K9: =-F8*J9/J11 -> 1517216.2 | L9: =K9/E9 -> 153.39361 | M9: =ROUND(H9,2) -> -0.98 | S9: 54002341 | T9: สารกาแฟโรบัสต้า | V9: =SUMIF(B:B,S9,E:E) -> -58005.2
B10: 57000004 | C10: เมล็ดกาแฟ Clean Robusta B | D10: KG | E10: 139.2 | F10: 22358.3 | H10: =E10/$E$8 -> -0.013856537 | I10: =F10/E10 -> 160.61997 | J10: 3 | K10: =-F8*J10/J11 -> 47912.091 | L10: =K10/E10 -> 344.19606 | M10: =ROUND(H10,2) -> -0.01 | S10: 57000003 | T10: เมล็ดกาแฟ Clean Robusta Size mix | V10: =SUMIF(B:B,S10,E:E) -> 57440.92
A11: 301000000205 Sum | E11: -15.6 | F11: 45922.41 | H11: =E11/$E$8 -> 0.0015528878 | J11: =SUM(J9:J10) -> 98 | K11: =SUM(K9:K10) -> 1565128.3 | M11: =SUM(M9:M10) -> -0.99 | N11: =SUM(H9:H10) -> -0.99844711 | O11: =-100%-N11 -> -0.0015528878 | P11: Adj Settlement Rule Done | S11: 57000004 | T11: เมล็ดกาแฟ Clean Robusta Size ต่ำกว่า S&M | V11: =SUMIF(B:B,S11,E:E) -> 399.3 | W11: =SUM(V9:V11) -> -164.98
A12: 301000000206 | B12: 54002340 | C12: สารกาแฟอาราบิก้า | D12: KG | E12: -15116.2 | F12: -3988715 | G12: =+E13+E14 -> 15042.12 | H12: =E12/$E$12 -> 1 | I12: =F12/E12 -> 263.87022 | Q12: 101
B13: 57000001 | C13: เมล็ดกาแฟ Clean Arabica Size L | D13: KG | E13: 14667.22 | F13: 3957069.3 | H13: =E13/$E$12 -> -0.97029809 | I13: =F13/E13 -> 269.79 | J13: 80 | K13: =-F12*J13/J15 -> 3844544.6 | L13: =K13/E13 -> 262.11815 | M13: =ROUND(H13,2) -> -0.97
B14: 57000002 | C14: เมล็ดกาแฟ Clean Arabica B | D14: KG | E14: 374.9 | F14: 101144.27 | H14: =E14/$E$12 -> -0.024801207 | I14: =F14/E14 -> 269.79 | J14: 3 | K14: =-F12*J14/J15 -> 144170.42 | L14: =K14/E14 -> 384.55701 | M14: =ROUND(H14,2) -> -0.02
A15: 301000000206 Sum | E15: -74.08 | F15: 69498.54 | H15: =E15/$E$12 -> 0.0049007026 | J15: =SUM(J13:J14) -> 83 | K15: =SUM(K13:K13) -> 3844544.6 | M15: =SUM(M13:M14) -> -0.99 | N15: =SUM(H13:H14) -> -0.9950993 | O15: =-100%-N15 -> -0.0049007026 | P15: Adj Settlement Rule Done | S15: คำถาม
A16: 301000000207 | B16: 54002340 | C16: สารกาแฟอาราบิก้า | D16: KG | E16: -14936.9 | F16: -3941403.1 | G16: =+E17 -> 14889.54 | H16: =E16/$E$16 -> 1 | I16: =F16/E16 -> 263.87022 | Q16: 101 | S16: 1. แต่ละ Batch การ Preclean จะใส่สารประมาณเท่าไหร่
B17: 57000001 | C17: เมล็ดกาแฟ Clean Arabica Size L | D17: KG | E17: 14889.54 | F17: 4017049 | H17: =E17/$E$16 -> -0.99682933 | I17: =F17/E17 -> 269.79 | J17: 80 | K17: =-F16*J17/J18 -> 3941403.1 | L17: =K17/E17 -> 264.70953 | M17: =ROUND(H17,2) -> -1 | S17: 2. แต่ละไซด์ที่รับคือตามจริงทั้งหมดหรือไม่
A18: 301000000207 Sum | E18: -47.36 | F18: 75645.92 | H18: =E18/$E$16 -> 0.0031706713 | J18: =SUM(J17) -> 80 | K18: =SUM(K17:K17) -> 3941403.1 | M18: =SUM(M17) -> -1 | N18: =SUM(H17:H17) -> -0.99682933 | O18: =-100%-N18 -> -0.0031706713 | P18: Adj Settlement Rule Done
A19: 301000000208 | B19: 54002340 | C19: สารกาแฟอาราบิก้า | D19: KG | E19: -4012.2 | F19: -1058854.2 | G19: =+E20+E21 -> 3959.2 | H19: =E19/$E$19 -> 1 | I19: =F19/E19 -> 263.90864 | Q19: 101
B20: 57000001 | C20: เมล็ดกาแฟ Clean Arabica Size L | D20: KG | E20: 3861 | F20: 1041556.1 | H20: =E20/$E$19 -> -0.96231494 | I20: =F20/E20 -> 269.76329 | J20: 80 | K20: =-F19*J20/J22 -> 1020582.4 | L20: =K20/E20 -> 264.3311 | M20: =ROUND(H20,2) -> -0.96
B21: 57000002 | C21: เมล็ดกาแฟ Clean Arabica B | D21: KG | E21: 98.2 | F21: 26595.51 | H21: =E21/$E$19 -> -0.02447535 | I21: =F21/E21 -> 270.83004 | J21: 3 | K21: =-F19*J21/J22 -> 38271.84 | L21: =K21/E21 -> 389.7336 | M21: =ROUND(H21,2) -> -0.02
A22: 301000000208 Sum | E22: -53 | F22: 9297.36 | H22: =E22/$E$19 -> 0.01320971 | J22: =SUM(J20:J21) -> 83 | K22: =SUM(K20:K20) -> 1020582.4 | M22: =SUM(M20:M21) -> -0.98 | N22: =SUM(H20:H21) -> -0.98679029 | O22: =-100%-N22 -> -0.01320971 | P22: Adj Settlement Rule Done
A23: 301000000212 | B23: 54002341 | C23: สารกาแฟโรบัสต้า | D23: KG | E23: -9988.2 | F23: -1556154.3 | G23: =+E24+E25 -> 9923.72 | H23: =E23/$E$23 -> 1 | I23: =F23/E23 -> 155.79927 | Q23: 101
B24: 57000003 | C24: เมล็ดกาแฟ Clean Robusta Size mix | D24: KG | E24: 9776.02 | F24: 1570224.3 | H24: =E24/$E$23 -> -0.97875693 | I24: =F24/E24 -> 160.62 | J24: 95 | K24: =-F23*J24/J26 -> 1508516.9 | L24: =K24/E24 -> 154.30788 | M24: =ROUND(H24,2) -> -0.98
B25: 57000004 | C25: เมล็ดกาแฟ Clean Robusta B | D25: KG | E25: 147.7 | F25: 23723.57 | H25: =E25/$E$23 -> -0.014787449 | I25: =F25/E25 -> 160.61997 | J25: 3 | K25: =-F23*J25/J26 -> 47637.376 | L25: =K25/E25 -> 322.52793 | M25: =ROUND(H25,2) -> -0.01
A26: 301000000212 Sum | E26: -64.48 | F26: 37793.63 | H26: =E26/$E$23 -> 0.0064556176 | J26: =SUM(J24:J25) -> 98 | K26: =SUM(K24:K25) -> 1556154.3 | M26: =SUM(M24:M25) -> -0.99 | N26: =SUM(H24:H25) -> -0.99354438 | O26: =-100%-N26 -> -0.0064556176 | P26: Adj Settlement Rule Done
A27: 301000000213 | B27: 54002340 | C27: สารกาแฟอาราบิก้า | D27: KG | E27: -15059.5 | F27: -3973753.6 | G27: =+E28+E29 -> 15030.94 | H27: =E27/$E$27 -> 1 | I27: =F27/E27 -> 263.87022 | Q27: 101
B28: 57000001 | C28: เมล็ดกาแฟ Clean Arabica Size L | D28: KG | E28: 14863.74 | F28: 4025695.3 | H28: =E28/$E$27 -> -0.9870009 | I28: =F28/E28 -> 270.84 | J28: 80 | K28: =-F27*J28/J30 -> 3830123.9 | L28: =K28/E28 -> 257.68238 | M28: =ROUND(H28,2) -> -0.99
B29: 57000002 | C29: เมล็ดกาแฟ Clean Arabica B | D29: KG | E29: 167.2 | F29: 45282.78 | H29: =E29/$E$27 -> -0.011102626 | I29: =F29/E29 -> 270.83002 | J29: 3 | K29: =-F27*J29/J30 -> 143629.65 | L29: =K29/E29 -> 859.02899 | M29: =ROUND(H29,2) -> -0.01
A30: 301000000213 Sum | E30: -28.56 | F30: 97224.55 | H30: =E30/$E$27 -> 0.0018964773 | J30: =SUM(J28:J29) -> 83 | K30: =SUM(K28:K29) -> 3973753.6 | M30: =SUM(M28) -> -0.99 | N30: =SUM(H28:H29) -> -0.99810352 | O30: =-100%-N30 -> -0.0018964773 | P30: Adj Settlement Rule Done
A31: 301000000214 | B31: 54002340 | C31: สารกาแฟอาราบิก้า | D31: KG | E31: -13021.2 | F31: -3436411.9 | G31: =+E32 -> 13008.94 | H31: =E31/$E$31 -> 1 | I31: =F31/E31 -> 263.909 | Q31: 101
B32: 57000001 | C32: เมล็ดกาแฟ Clean Arabica Size L | D32: KG | E32: 13008.94 | F32: 3523341.3 | H32: =E32/$E$31 -> -0.99905846 | I32: =F32/E32 -> 270.84 | J32: 80 | K32: =-F31*J32/J33 -> 3436411.9 | L32: =K32/E32 -> 264.15772 | M32: =ROUND(H32,2) -> -1
A33: 301000000214 Sum | E33: -12.26 | F33: 86929.38 | H33: =E33/$E$31 -> 0.00094154149 | J33: =SUM(J32) -> 80 | K33: =SUM(K32:K32) -> 3436411.9 | M33: =SUM(M32) -> -1 | N33: =SUM(H32:H32) -> -0.99905846 | O33: =-100%-N33 -> -0.00094154149 | P33: Adj Settlement Rule Done
A34: 301000000215 | B34: 54002340 | C34: สารกาแฟอาราบิก้า | D34: KG | E34: -5017.3 | F34: -1324110.6 | G34: =E35+E36 -> 4977.72 | H34: =E34/$E$34 -> 1 | I34: =F34/E34 -> 263.909 | Q34: 101
B35: 57000001 | C35: เมล็ดกาแฟ Clean Arabica Size L | D35: KG | E35: 4806 | F35: 1301657 | H35: =E35/$E$34 -> -0.95788572 | I35: =F35/E35 -> 270.84 | J35: 80 | K35: =-F34*J35/J37 -> 1276251.2 | L35: =K35/E35 -> 265.55373 | M35: =ROUND(H35,2) -> -0.96
B36: 57000002 | C36: เมล็ดกาแฟ Clean Arabica B | D36: KG | E36: 171.72 | F36: 46506.93 | H36: =E36/$E$34 -> -0.034225579 | I36: =F36/E36 -> 270.83001 | J36: 3 | K36: =-F34*J36/J37 -> 47859.421 | L36: =K36/E36 -> 278.70616 | M36: =ROUND(H36,2) -> -0.03
A37: 301000000215 Sum | E37: -39.58 | F37: 24053.32 | H37: =E37/$E$34 -> 0.0078887051 | J37: =SUM(J35:J36) -> 83 | K37: =SUM(K35:K36) -> 1324110.7 | M37: =SUM(M35:M36) -> -0.99 | N37: =SUM(H35:H36) -> -0.99211129 | O37: =-100%-N37 -> -0.0078887051 | P37: Adj Settlement Rule Done
A38: 301000000216 | B38: 54002340 | C38: สารกาแฟอาราบิก้า | D38: KG | E38: -3069.7 | F38: -810121.47 | G38: =E39+E40 -> 3051.06 | H38: =E38/$E$38 -> 1 | I38: =F38/E38 -> 263.909 | Q38: 101
B39: 57000001 | C39: เมล็ดกาแฟ Clean Arabica Size L | D39: KG | E39: 3015.18 | F39: 816631.35 | H39: =E39/$E$38 -> -0.98223931 | I39: =F39/E39 -> 270.84 | J39: 80 | K39: =-F38*J39/J41 -> 780839.97 | L39: =K39/E39 -> 258.9696 | M39: =ROUND(H39,2) -> -0.98
B40: 57000002 | C40: เมล็ดกาแฟ Clean Arabica B | D40: KG | E40: 35.88 | F40: 9717.38 | H40: =E40/$E$38 -> -0.011688439 | I40: =F40/E40 -> 270.82999 | J40: 3 | K40: =-F38*J40/J41 -> 29281.499 | L40: =K40/E40 -> 816.09529 | M40: =ROUND(H40,2) -> -0.01
A41: 301000000216 Sum | E41: -18.64 | F41: 16227.26 | H41: =E41/$E$38 -> 0.0060722546 | J41: =SUM(J39:J40) -> 83 | K41: =SUM(K39:K40) -> 810121.47 | M41: =SUM(M39:M40) -> -0.99 | N41: =SUM(H39:H40) -> -0.99392775 | O41: =-100%-N41 -> -0.0060722546 | P41: Adj Settlement Rule Done
...

Sheet 302
A1: Group order | B1: 302 | C1: ห้อง Roasting | I1: ในห้องคั่วไม่มีเครื่องชั่งจะมาคำนวณกลับในห้องแพ็คเลย
A3: Row Labels | B3: Material | C3: Material description | D3: EUn | E3: Sum of Quantity in UnE | F3: Sum of Amt.in Loc.Cur. | G3: ใส่สาร | H3: สัดส่วนผสม | I3: สัดส่วน | K3: ราคาต่อหน่วย | L3: Yeild | M3: Loss | N3: สูตร FG | O3: Por Ver
A4: 302000000311 | B4: 57000001 | C4: เมล็ดกาแฟ Clean Arabica Size L | D4: KG | E4: -2244.2 | F4: -605462.72 | G4: =SUM(E4:E6) -> -2885.08 | H4: =E4/G4 -> 0.77786405 | I4: =E4/E7 -> -0.95512098 | K4: =F4/E4 -> 269.79
B5: 57000002 | C5: เมล็ดกาแฟ Clean Arabica B | D5: KG | E5: -60.04 | F5: -16198.19 | H5: =E5/G4 -> 0.020810515 | I5: =E5/E7 -> -0.025552742 | K5: =F5/E5 -> 269.78997
B6: 57000003 | C6: เมล็ดกาแฟ Clean Robusta Size mix | D6: KG | E6: -580.84 | F6: -93294.52 | H6: =E6/G4 -> 0.20132544 | I6: =E6/E7 -> -0.24720277 | K6: =F6/E6 -> 160.62
B7: 57000103 | C7: เมล็ดกาแฟคั่ว calibrate A80+R20 | D7: KG | E7: 2349.65 | F7: 761921.01 | H7: =E7/G4 -> -0.81441416 | I7: =E7/E7 -> 1 | K7: =F7/E7 -> 324.27
A8: 302000000311 Sum | E8: -535.43 | F8: 46965.58 | I8: =E8/G4 -> 0.18558584 | K8: =F8/E8 -> -87.71563 | L8: =E7/G4 -> -0.81441416 | M8: =100%+L8 -> 0.18558584 | N8: ='303 '!AM15 -> เมล็ดกาแฟ CPR Coffee Bean MF. 500 G. | O8: 301
A9: 302000000310 | B9: 57000001 | C9: เมล็ดกาแฟ Clean Arabica Size L | D9: KG | E9: -5184.8 | F9: -1398807.2 | G9: =SUM(E9:E10) -> -6482.07 | H9: =E9/G9 -> 0.79986794 | I9: =E9/E11 -> -0.99478509 | K9: =F9/E9 -> 269.79
B10: 57000003 | C10: เมล็ดกาแฟ Clean Robusta Size mix | D10: KG | E10: -1297.27 | F10: -208367.51 | H10: =E10/G9 -> 0.20013206 | I10: =E10/E11 -> -0.24890157 | K10: =F10/E10 -> 160.62
B11: 57000100 | C11: เมล็ดกาแฟคั่ว A80 + R20 | D11: KG | E11: 5211.98 | F11: 1690088.8 | H11: =E11/G9 -> -0.80406105 | I11: =E11/E11 -> 1 | K11: =F11/E11 -> 324.27
A12: 302000000310 Sum | E12: -1270.09 | F12: 82914.05 | I12: =E12/G9 -> 0.19593895 | K12: =F12/E12 -> -65.282027 | L12: =E11/G9 -> -0.80406105 | M12: =100%+L12 -> 0.19593895 | N12: ='303 '!AM21 -> GOLD BLEND ALL CAFE' ขนาด 500 G. | O12: 401
A13: 302000000312 | B13: 57000001 | C13: เมล็ดกาแฟ Clean Arabica Size L | D13: KG | E13: -120 | F13: -32374.8 | G13: =SUM(E13:E14) -> -240 | H13: =E13/$G$13 -> 0.5 | I13: =E13/E15 -> -0.58252427 | K13: =F16/E16 -> -225.70059
B14: 57000002 | C14: เมล็ดกาแฟ Clean Arabica B | D14: KG | E14: -120 | F14: -32374.8 | H14: =E14/$G$13 -> 0.5 | I14: =E14/E15 -> -0.58252427 | K14: =F17/E17 -> 269.79
B15: 57000101 | C15: เมล็ดกาแฟคั่ว A100 | D15: KG | E15: 206 | F15: 72423.42 | H15: =E15/$G$13 -> -0.85833333 | I15: =E15/E15 -> 1 | K15: =F18/E18 -> 160.62
A16: 302000000312 Sum | E16: -34 | F16: 7673.82 | I16: =E16/G13 -> 0.14166667 | K16: =F20/E20 -> -66.391017 | L16: =E15/G13 -> -0.85833333 | M16: =100%+L16 -> 0.14166667 | N16: ='303 '!AM28 -> เมล็ดกาแฟคั่ว Classic 1 bag ขนาด 500 G. | O16: 201
A17: 302000000313 | B17: 57000001 | C17: เมล็ดกาแฟ Clean Arabica Size L | D17: KG | E17: -10176.2 | F17: -2745437 | G17: =SUM(E17:E18) -> -12724.6 | H17: =E17/$G$17 -> 0.79972651 | I17: =E17/E19 -> -0.99397046 | K17: =F17/E17 -> 269.79
B18: 57000003 | C18: เมล็ดกาแฟ Clean Robusta Size mix | D18: KG | E18: -2548.4 | F18: -409324.01 | H18: =E18/$G$17 -> 0.20027349 | I18: =E18/E19 -> -0.24891751 | K18: =F18/E18 -> 160.62
B19: 57000100 | C19: เมล็ดกาแฟคั่ว A80 + R20 | D19: KG | E19: 10237.93 | F19: 3319853.6 | H19: =E19/$G$17 -> -0.80457775 | I19: =E19/E19 -> 1 | K19: =F19/E19 -> 324.27
A20: 302000000313 Sum | E20: -2486.67 | F20: 165092.55 | I20: =E20/G17 -> 0.19542225 | K20: =F20/E20 -> -66.391017 | L20: =E19/G17 -> -0.80457775 | M20: =100%+L20 -> 0.19542225 | N20: ='303 '!AM34 -> GOLD BLEND ALL CAFE' ขนาด 500 G. | O20: 401
A21: 302000000314 | B21: 57000001 | C21: เมล็ดกาแฟ Clean Arabica Size L | D21: KG | E21: -8599.2 | F21: -2319978.2 | G21: =SUM(E21:E23) -> -12004.98 | H21: =E21/$G$21 -> 0.71630273 | I21: =E21/E24 -> -0.89148203 | K21: =F21/E21 -> 269.79
B22: 57000002 | C22: เมล็ดกาแฟ Clean Arabica B | D22: KG | E22: -1001.7 | F22: -270248.64 | H22: =E22/$G$21 -> 0.083440372 | I22: =E22/E24 -> -0.10384658 | K22: =F22/E22 -> 269.79
B23: 57000003 | C23: เมล็ดกาแฟ Clean Robusta Size mix | D23: KG | E23: -2404.08 | F23: -386143.33 | H23: =E23/$G$21 -> 0.20025689 | I23: =E23/E24 -> -0.2492318 | K23: =F23/E23 -> 160.62
B24: 57000100 | C24: เมล็ดกาแฟคั่ว A80 + R20 | D24: KG | E24: 9645.96 | F24: 3127895.5 | H24: =E24/$G$21 -> -0.80349655 | I24: =E24/E24 -> 1 | K24: =F24/E24 -> 324.27
A25: 302000000314 Sum | E25: -2359.02 | F25: 151525.31 | I25: =E25/G21 -> 0.19650345 | K25: =F25/E25 -> -64.232313 | L25: =E24/G21 -> -0.80349655 | M25: =100%+L25 -> 0.19650345 | N25: ='303 '!AM40 -> GOLD BLEND ALL CAFE' ขนาด 500 G. | O25: 401
A26: 302000000315 | B26: 57000001 | C26: เมล็ดกาแฟ Clean Arabica Size L | D26: KG | E26: -7681.9 | F26: -2072499.8 | G26: =SUM(E26:E27) -> -9605.34 | H26: =E26/$G$26 -> 0.79975305 | I26: =E26/E28 -> -0.99080763 | K26: =F26/E26 -> 269.79
B27: 57000003 | C27: เมล็ดกาแฟ Clean Robusta Size mix | D27: KG | E27: -1923.44 | F27: -308942.93 | H27: =E27/$G$26 -> 0.20024695 | I27: =E27/E28 -> -0.24808433 | K27: =F27/E27 -> 160.62
B28: 57000100 | C28: เมล็ดกาแฟคั่ว A80 + R20 | D28: KG | E28: 7753.17 | F28: 2514120.4 | H28: =E28/$G$26 -> -0.80717289 | I28: =E28/E28 -> 1 | K28: =F28/E28 -> 324.27
A29: 302000000315 Sum | E29: -1852.17 | F29: 132677.71 | I29: =E29/G26 -> 0.19282711 | K29: =F29/E29 -> -71.633657 | L29: =E28/G26 -> -0.80717289 | M29: =100%+L29 -> 0.19282711 | N29: ='303 '!AM46 -> GOLD BLEND ALL CAFE' ขนาด 500 G. | O29: 401
A30: 302000000316 | B30: 57000001 | C30: เมล็ดกาแฟ Clean Arabica Size L | D30: KG | E30: -9299.5 | F30: -2518676.6 | G30: =SUM(E30:E32) -> -12003.64 | H30: =E30/$G$30 -> 0.77472333 | I30: =E30/E33 -> -0.96106347 | K30: =F30/E30 -> 270.84
B31: 57000002 | C31: เมล็ดกาแฟ Clean Arabica B | D31: KG | E31: -300.56 | F31: -81400.66 | H31: =E31/$G$30 -> 0.025039071 | I31: =E31/E33 -> -0.031061588 | K31: =F31/E31 -> 270.82998
B32: 57000003 | C32: เมล็ดกาแฟ Clean Robusta Size mix | D32: KG | E32: -2403.58 | F32: -384404.55 | H32: =E32/$G$30 -> 0.20023759 | I32: =E32/E33 -> -0.24839969 | K32: =F32/E32 -> 159.93
B33: 57000100 | C33: เมล็ดกาแฟคั่ว A80 + R20 | D33: KG | E33: 9676.26 | F33: 3146139.2 | H33: =E33/$G$30 -> -0.80611048 | I33: =E33/E33 -> 1 | K33: =F33/E33 -> 325.14
A34: 302000000316 Sum | E34: -2327.38 | F34: 161657.39 | I34: =E34/G30 -> 0.19388952 | K34: =F34/E34 -> -69.458958 | L34: =E33/G30 -> -0.80611048 | M34: =100%+L34 -> 0.19388952 | N34: ='303 '!AM52 -> GOLD BLEND ALL CAFE' ขนาด 500 G. | O34: 401
A35: 302000000317 | B35: 57000001 | C35: เมล็ดกาแฟ Clean Arabica Size L | D35: KG | E35: -8942.2 | F35: -2421905.5 | G35: =SUM(E35:E37) -> -12483.42 | H35: =E35/$G$35 -> 0.71632613 | I35: =E35/E38 -> -0.88883455 | K35: =F35/E35 -> 270.84
B36: 57000002 | C36: เมล็ดกาแฟ Clean Arabica B | D36: KG | E36: -1043.58 | F36: -282632.77 | H36: =E36/$G$35 -> 0.083597283 | I36: =E36/E38 -> -0.1037295 | K36: =F36/E36 -> 270.83
B37: 57000003 | C37: เมล็ดกาแฟ Clean Robusta Size mix | D37: KG | E37: -2497.64 | F37: -399447.57 | H37: =E37/$G$35 -> 0.20007658 | I37: =E37/E38 -> -0.24825979 | K37: =F37/E37 -> 159.93
B38: 57000100 | C38: เมล็ดกาแฟคั่ว A80 + R20 | D38: KG | E38: 10060.59 | F38: 3271100.2 | H38: =E38/$G$35 -> -0.80591617 | I38: =E38/E38 -> 1 | K38: =F38/E38 -> 325.14
A39: 302000000317 Sum | E39: -2422.83 | F39: 167114.44 | I39: =E39/G35 -> 0.19408383 | K39: =F39/E39 -> -68.974893 | L39: =E38/G35 -> -0.80591617 | M39: =100%+L39 -> 0.19408383 | N39: ='303 '!AM58 -> GOLD BLEND ALL CAFE' ขนาด 500 G. | O39: 401
A40: 302000000318 | B40: 57000001 | C40: เมล็ดกาแฟ Clean Arabica Size L | D40: KG | E40: -8601 | F40: -2329494.8 | G40: =SUM(E40:E42) -> -12006.8 | H40: =E40/$G$40 -> 0.71634407 | I40: =E40/$E$43 -> -0.89169452 | K40: =F40/E40 -> 270.84
B41: 57000002 | C41: เมล็ดกาแฟ Clean Arabica B | D41: KG | E41: -1003.08 | F41: -271664.16 | H41: =E41/$G$40 -> 0.083542659 | I41: =E41/$E$43 -> -0.10399267 | K41: =F41/E41 -> 270.83
...

Sheet 303 
A1: Group order | B1: 303 | C1: เริ่มผลิต 1.7.2026 - 31.7.2026 | E1: ห้อง Packaging | I1: 58-10 = 20 ถุง
I2: 58-6 = 6 ถุง | T2: ปกติซองกับวาล์วจะเสียปริมาณเท่ากันแต่ใส่หมายเหตุและจำนวนแค่เฉพาะที่ซอง | AI2: ใส่ 507 kg. --> ยังตัดไม่ครบไหม
A3: Row Labels | B3: Material | C3: Material description | D3: EUn | E3: Sum of Quantity in UnE | F3: Sum of Amt.in Loc.Cur. | G3: check | H3: Diff | I3: ถุง +ลังเสีย | J3: Diff | K3: Por Ver | L3: วันที่ | M3: QA เบิก (ถุง) | N3: ห้องคั่ว(g) | O3: ห้องแพ็ค(g) | P3: รวม(kg) | Q3: Diff | R3: เครื่องจักร | S3: QA เบิก | T3: โรบอทตีแตก | U3: วาล์วเสีย | V3: สตก เสีย | W3: เปลี่ยนตั้งฟิล์ม | X3: ฟิล์มยับ | Y3: นน.ขาด | Z3: ดับเบิ้ล | AA3: ซองวาล์วแตก | AB3: Repack | AC3: ระบุวันที่ผิด (ซอง) | AE3: รวมซองเสีย | AF3: Diff | AI3: ต่อหน่วย | AJ3: Loss | AK3: Yeild | AL3: kg | AM3: สูตร FG | AN3: G | AO3: Kg
A4: 303000000309 | B4: 58000002 | C4: WIPF WICOVALVE W009 | D4: PC | E4: -1617 | F4: -1367.61 | G4: =E4+E7 -> -97 | H4: =G4+P4 -> -97 | K4: 101 | L4: 01.07.2026 | M4: 0 | N4: 0 | O4: 0 | P4: =SUM(N4:O4)/1000 -> 0 | Q4: =G8+P4 -> 0 | R4: 0 | S4: 0 | T4: 0 | U4: 97 | W4: 42 | X4: 0 | Y4: 10 | Z4: 20 | AB4: 25 | AE4: =SUM(W4:AC4) -> 97 | AF4: =U4-AE4 -> 0 | AH4: =G4/E4 -> 0.059987631 | AI4: =F4/E4 -> 0.84576994 | AJ4: =100%+AK4 -> 0 | AK4: =(E7*500/1000)/E8 -> -1
B5: 58000010 | C5: (4seal) กล่องกระดาษ5ชั้น 450*330*300 mm | D5: PC | E5: -76 | F5: -1672 | G5: =(E7/6)+E5 -> 177.33333 | AH5: =G5/E5 -> -2.3333333 | AI5: =F5/E5 -> 22
B6: 58000025 | C6: Film roll Nologo 500g.420mm*900m | D6: PC | E6: -1617 | F6: -2775.85 | G6: =E6+E7 -> -97 | AH6: =G6/E6 -> 0.059987631 | AI6: =F6/E6 -> 1.7166667
B7: 59000004 | C7: Super Blend 500 G. | D7: BAG | E7: 1520 | F7: 217466.4 | G7: =(E7*500)/1000000 -> 0.76 | I7: =(E7/20)+R4+S4+T4 -> 76 | J7: =E5+I7 -> 0 | AH7: =G7/E7 -> 0.0005 | AI7: =F7/E7 -> 143.07 | AL7: =AI7*2 -> 286.14 | AN7: =E7*500 -> 760000 | AO7: =AN7/1000 -> 760
B8: 57000102 | C8: เมล็ดกาแฟคั่ว A40+R60 | D8: KG | E8: -760 | F8: -204956.8 | G8: =((E8*2)+E7)/2 -> 0 | AH8: =G8/E8 -> 0 | AI8: =F8/E8 -> 269.68
A9: 303000000309 Sum | E9: -2550 | F9: 6694.14 | AM9: =C7 -> Super Blend 500 G.
A10: 303000000310 | B10: 57000103 | C10: เมล็ดกาแฟคั่ว calibrate A80+R20 | D10: KG | E10: -2349.65 | F10: -761921.01 | G10: =((E10*2)+E14)/2 -> -1.15 | H10: =G10+P10 -> -9.1038288e-14 | K10: 101 | L10: 01.07.2026 | M10: 2 | N10: 0 | O10: 1150 | P10: =SUM(N10:O10)/1000 -> 1.15 | Q10: =G10+P10 -> -9.1038288e-14 | R10: 1 | S10: 0 | T10: 0 | U10: 297 | V10: 0 | W10: 173 | X10: 0 | Y10: 13 | Z10: 30 | AB10: 81 | AE10: =SUM(W10:AC10) -> 297 | AF10: =U10-AE10 -> 0 | AH10: =G10/E10 -> 0.0004894346 | AI10: =F10/E10 -> 324.27 | AJ10: =100%+AK10 -> 0.0004894346 | AK10: =(E14*500/1000)/E10 -> -0.99951057
B11: 58000002 | C11: WIPF WICOVALVE W009 | D11: PC | E11: -4994 | F11: -4223.76 | G11: =E11+E14 -> -297 | AH11: =G11/E11 -> 0.059471366 | AI11: =F11/E11 -> 0.84576692
B12: 58000003 | C12: Film roll Gold blend 420mm*900m | D12: PC | E12: -4994 | F12: -10280.88 | G12: =E12+E14 -> -297 | AH12: =G12/E12 -> 0.059471366 | AI12: =F12/E12 -> 2.0586464
B13: 58000005 | C13: ลังกระดาษ 3กก. 287*240*177 mm. (No Logo) | D13: PC | E13: -784 | F13: -3920 | G13: =(E14/6)+E13 -> -1.1666667 | I13: =(E14/6)+R10+S10+T10 -> 783.83333 | J13: =E13+I13 -> -0.16666667 | AH13: =G13/E13 -> 0.0014880952 | AI13: =F13/E13 -> 5 | AL13: =AI14*2 -> 338.72 | AN13: =E14*500 -> 2348500 | AO13: =AN13/1000 -> 2348.5
B14: 59000001 | C14: เมล็ดกาแฟ CPR Coffee Bean MF. 500 G. | D14: BAG | E14: 4697 | F14: 795483.92 | G14: =(E14*500)/1000000 -> 2.3485 | AH14: =G14/E14 -> 0.0005 | AI14: =F14/E14 -> 169.36
A15: 303000000310 Sum | E15: -8424.65 | F15: 15138.27 | AM15: =C14 -> เมล็ดกาแฟ CPR Coffee Bean MF. 500 G.
